<?xml version="1.0" encoding="utf-8"?>
<!-- This URDF was automatically created by SolidWorks to URDF Exporter! Originally created by Stephen Brawner (brawner@gmail.com) 
     Commit Version: 1.5.1-0-g916b5db  Build Version: 1.5.7152.31018
     For more information, please see http://wiki.ros.org/sw_urdf_exporter -->
<robot
  name="6_DOF_Robotics_Arm_Final.URDF">
  <link
    name="base_link">
    <inertial>
      <origin
        xyz="0.0541161429743802 -0.0691963813756943 0.064985086858552"
        rpy="0 0 0" />
      <mass
        value="0.188163504906416" />
      <inertia
        ixx="0.000128573783828188"
        ixy="1.51304442258009E-08"
        ixz="3.78080182986574E-07"
        iyy="5.15774857394592E-05"
        iyz="3.16384894484948E-08"
        izz="0.000128447911808392" />
    </inertial>
    <visual>
      <origin
        xyz="0 0 0"
        rpy="0 0 0" />
      <geometry>
        <mesh
          filename="package://6_DOF_Robotics_Arm_Final.URDF/meshes/base_link.STL" />
      </geometry>
      <material
        name="">
        <color
          rgba="0.898039215686275 0.917647058823529 0.929411764705882 1" />
      </material>
    </visual>
    <collision>
      <origin
        xyz="0 0 0"
        rpy="0 0 0" />
      <geometry>
        <mesh
          filename="package://6_DOF_Robotics_Arm_Final.URDF/meshes/base_link.STL" />
      </geometry>
    </collision>
  </link>
  <link
    name="Servo_1">
    <inertial>
      <origin
        xyz="0.00262003457259923 -0.0160254110277553 0.0550034622142633"
        rpy="0 0 0" />
      <mass
        value="0.0697171437888397" />
      <inertia
        ixx="3.26215924184291E-05"
        ixy="4.46853033725565E-07"
        ixz="-3.80890294963114E-07"
        iyy="1.97176889077533E-05"
        iyz="-1.25498494824953E-08"
        izz="2.11845689493179E-05" />
    </inertial>
    <visual>
      <origin
        xyz="0 0 0"
        rpy="0 0 0" />
      <geometry>
        <mesh
          filename="package://6_DOF_Robotics_Arm_Final.URDF/meshes/Servo_1.STL" />
      </geometry>
      <material
        name="">
        <color
          rgba="0.898039215686275 0.917647058823529 0.929411764705882 1" />
      </material>
    </visual>
    <collision>
      <origin
        xyz="0 0 0"
        rpy="0 0 0" />
      <geometry>
        <mesh
          filename="package://6_DOF_Robotics_Arm_Final.URDF/meshes/Servo_1.STL" />
      </geometry>
    </collision>
  </link>
  <joint
    name="J_Servo_1"
    type="revolute">
    <origin
      xyz="0.0606296506744766 -0.0800512931407774 0.0695824653839695"
      rpy="0 0 0" />
    <parent
      link="base_link" />
    <child
      link="Servo_1" />
    <axis
      xyz="0 0 1" />
    <limit
      lower="0"
      upper="6.284"
      effort="10"
      velocity="1" />
  </joint>
  <link
    name="Servo_2">
    <inertial>
      <origin
        xyz="-0.0488056125467775 0.000919860623275343 -0.0285440113804766"
        rpy="0 0 0" />
      <mass
        value="0.0477462491167637" />
      <inertia
        ixx="2.99677521324419E-05"
        ixy="3.00613423543034E-07"
        ixz="1.32348898008484E-19"
        iyy="4.59119208446105E-05"
        iyz="2.58385191545037E-19"
        izz="2.08534898617625E-05" />
    </inertial>
    <visual>
      <origin
        xyz="0 0 0"
        rpy="0 0 0" />
      <geometry>
        <mesh
          filename="package://6_DOF_Robotics_Arm_Final.URDF/meshes/Servo_2.STL" />
      </geometry>
      <material
        name="">
        <color
          rgba="0.894117647058823 0.913725490196078 0.929411764705882 1" />
      </material>
    </visual>
    <collision>
      <origin
        xyz="0 0 0"
        rpy="0 0 0" />
      <geometry>
        <mesh
          filename="package://6_DOF_Robotics_Arm_Final.URDF/meshes/Servo_2.STL" />
      </geometry>
    </collision>
  </link>
  <joint
    name="J_Servo_2"
    type="revolute">
    <origin
      xyz="0.0279012310885413 0.000579645930327333 0.0702922239700387"
      rpy="1.57079632679485 0 1.60231836298091" />
    <parent
      link="Servo_1" />
    <child
      link="Servo_2" />
    <axis
      xyz="0 0 -1" />
    <limit
      lower="0"
      upper="6.284"
      effort="10"
      velocity="1" />
  </joint>
  <link
    name="Servo_3">
    <inertial>
      <origin
        xyz="-0.0288731372298697 -5.72985396471715E-05 -0.0265881802115869"
        rpy="0 0 0" />
      <mass
        value="0.0766218826066926" />
      <inertia
        ixx="2.05074534096184E-05"
        ixy="8.42659579216293E-07"
        ixz="2.5652756742512E-08"
        iyy="3.48454330111084E-05"
        iyz="-3.82276648769762E-07"
        izz="2.13668806435349E-05" />
    </inertial>
    <visual>
      <origin
        xyz="0 0 0"
        rpy="0 0 0" />
      <geometry>
        <mesh
          filename="package://6_DOF_Robotics_Arm_Final.URDF/meshes/Servo_3.STL" />
      </geometry>
      <material
        name="">
        <color
          rgba="0.501960784313725 0.501960784313725 0.501960784313725 1" />
      </material>
    </visual>
    <collision>
      <origin
        xyz="0 0 0"
        rpy="0 0 0" />
      <geometry>
        <mesh
          filename="package://6_DOF_Robotics_Arm_Final.URDF/meshes/Servo_3.STL" />
      </geometry>
    </collision>
  </link>
  <joint
    name="J_Servo_3"
    type="revolute">
    <origin
      xyz="-0.101981892465741 0.00192209664904994 0"
      rpy="0 0 0" />
    <parent
      link="Servo_2" />
    <child
      link="Servo_3" />
    <axis
      xyz="0 0 -1" />
    <limit
      lower="0"
      upper="6.284"
      effort="10"
      velocity="1" />
  </joint>
  <link
    name="Servo_4">
    <inertial>
      <origin
        xyz="0.0122098036922746 0.0179347468629155 -0.0265930884325671"
        rpy="0 0 0" />
      <mass
        value="0.0916880384684618" />
      <inertia
        ixx="2.14724173590942E-05"
        ixy="3.42590346144344E-07"
        ixz="3.81192932345461E-07"
        iyy="1.43954469485834E-05"
        iyz="-8.10511823847165E-08"
        izz="1.44466732117496E-05" />
    </inertial>
    <visual>
      <origin
        xyz="0 0 0"
        rpy="0 0 0" />
      <geometry>
        <mesh
          filename="package://6_DOF_Robotics_Arm_Final.URDF/meshes/Servo_4.STL" />
      </geometry>
      <material
        name="">
        <color
          rgba="0.501960784313725 0.501960784313725 0.501960784313725 1" />
      </material>
    </visual>
    <collision>
      <origin
        xyz="0 0 0"
        rpy="0 0 0" />
      <geometry>
        <mesh
          filename="package://6_DOF_Robotics_Arm_Final.URDF/meshes/Servo_4.STL" />
      </geometry>
    </collision>
  </link>
  <joint
    name="J_Servo_4"
    type="revolute">
    <origin
      xyz="-0.0962728900578039 0.0052534478374367 -0.000255638957103441"
      rpy="0 0 0" />
    <parent
      link="Servo_3" />
    <child
      link="Servo_4" />
    <axis
      xyz="0 0 -1" />
    <limit
      lower="0"
      upper="6.284"
      effort="10"
      velocity="1" />
  </joint>
  <link
    name="Servo_5">
    <inertial>
      <origin
        xyz="0.0203981116824153 0.0163720259652086 0.0231459747844466"
        rpy="0 0 0" />
      <mass
        value="0.0375236817987459" />
      <inertia
        ixx="2.28913795416027E-06"
        ixy="2.89615561432946E-07"
        ixz="1.19849152770873E-08"
        iyy="7.17556838008689E-06"
        iyz="-5.99844580707235E-10"
        izz="6.42971802667197E-06" />
    </inertial>
    <visual>
      <origin
        xyz="0 0 0"
        rpy="0 0 0" />
      <geometry>
        <mesh
          filename="package://6_DOF_Robotics_Arm_Final.URDF/meshes/Servo_5.STL" />
      </geometry>
      <material
        name="">
        <color
          rgba="0.792156862745098 0.819607843137255 0.933333333333333 1" />
      </material>
    </visual>
    <collision>
      <origin
        xyz="0 0 0"
        rpy="0 0 0" />
      <geometry>
        <mesh
          filename="package://6_DOF_Robotics_Arm_Final.URDF/meshes/Servo_5.STL" />
      </geometry>
    </collision>
  </link>
  <joint
    name="J_Servo_5"
    type="revolute">
    <origin
      xyz="0.025501 0.056504 -0.01756"
      rpy="-1.6334 1.5708 -0.06813" />
    <parent
      link="Servo_4" />
    <child
      link="Servo_5" />
    <axis
      xyz="0 0 -1" />
    <limit
      lower="0"
      upper="6.284"
      effort="10"
      velocity="1" />
  </joint>
  <link
    name="Left">
    <inertial>
      <origin
        xyz="-0.000140263053481193 0.0378775395719271 -0.000487111945177948"
        rpy="0 0 0" />
      <mass
        value="0.00434842106430857" />
      <inertia
        ixx="1.03738495264322E-06"
        ixy="-1.70472757322792E-07"
        ixz="1.32348898008484E-23"
        iyy="1.37579602742187E-07"
        iyz="5.16987882845642E-23"
        izz="1.16958728171687E-06" />
    </inertial>
    <visual>
      <origin
        xyz="0 0 0"
        rpy="0 0 0" />
      <geometry>
        <mesh
          filename="package://6_DOF_Robotics_Arm_Final.URDF/meshes/Left.STL" />
      </geometry>
      <material
        name="">
        <color
          rgba="0.792156862745098 0.819607843137255 0.933333333333333 1" />
      </material>
    </visual>
    <collision>
      <origin
        xyz="0 0 0"
        rpy="0 0 0" />
      <geometry>
        <mesh
          filename="package://6_DOF_Robotics_Arm_Final.URDF/meshes/Left.STL" />
      </geometry>
    </collision>
  </link>
  <joint
    name="J_Left"
    type="revolute">
    <origin
      xyz="-0.0142790759972986 -0.0013876020851486 0.0250000000000311"
      rpy="1.5707963267949 -0.000411700793667653 -0.0746500953323074" />
    <parent
      link="Servo_5" />
    <child
      link="Left" />
    <axis
      xyz="0 0 1" />
    <limit
      lower="0"
      upper="6.284"
      effort="10"
      velocity="1" />
  </joint>
  <link
    name="Right">
    <inertial>
      <origin
        xyz="-0.00153120570884525 0.0265662084691654 0.00130600384235494"
        rpy="0 0 0" />
      <mass
        value="0.00629455198975266" />
      <inertia
        ixx="1.097316085587E-06"
        ixy="1.7579506983526E-07"
        ixz="9.92616735063633E-23"
        iyy="1.74975030550982E-07"
        iyz="-5.60414865004676E-22"
        izz="1.26288025520034E-06" />
    </inertial>
    <visual>
      <origin
        xyz="0 0 0"
        rpy="0 0 0" />
      <geometry>
        <mesh
          filename="package://6_DOF_Robotics_Arm_Final.URDF/meshes/Right.STL" />
      </geometry>
      <material
        name="">
        <color
          rgba="0.792156862745098 0.819607843137255 0.933333333333333 1" />
      </material>
    </visual>
    <collision>
      <origin
        xyz="0 0 0"
        rpy="0 0 0" />
      <geometry>
        <mesh
          filename="package://6_DOF_Robotics_Arm_Final.URDF/meshes/Right.STL" />
      </geometry>
    </collision>
  </link>
  <joint
    name="J_Right"
    type="revolute">
    <origin
      xyz="0.0122841327370988 -0.00287284338994137 0.0249999999999963"
      rpy="1.5707963267949 -0.000411700793667649 -0.0746500953323066" />
    <parent
      link="Servo_5" />
    <child
      link="Right" />
    <axis
      xyz="0 0 -1" />
    <limit
      lower="0"
      upper="6.284"
      effort="10"
      velocity="1" />
  </joint>
</robot>